Workbook

Sheet シート1
A1: Title | B1: Permalink | C1: Languages | D1: Artists | E1: collections&Series | F1: collections | G1: Series | H1: artist_name | I1: issued | J1: issued_ja | K1: total_supply | L1: real_supply | M1: card_num | N1: collections+emoji | P1: 16
A2: PEPEBAZAAR | B2: https://rarejapanesenfts.com/nft/pepebazaar/ | C2: English | D2: kappepe | E2: Badger Capsule>Series 1 | F2: =IFERROR(__xludf.DUMMYFUNCTION("SPLIT(E2,"">"")"),"Badger Capsule") -> Badger Capsule | G2: =IFERROR(__xludf.DUMMYFUNCTION("""COMPUTED_VALUE"""),"Series 1") -> Series 1 | H2: kappepe | I2: Nov 2021 | J2: 44501 | K2: 250 | L2: 250 | M2: 12 | N2: Badger Capsule | P2: =VLOOKUP(D2,'シート2'!A:B, 2, 0) -> @kartanbitcoin
A3: IDOJAWAN | B3: https://rarejapanesenfts.com/nft/idojawan/ | C3: English | D3: CHUNRI | E3: Badger Capsule>Series 1 | F3: =IFERROR(__xludf.DUMMYFUNCTION("SPLIT(E3,"">"")"),"Badger Capsule") -> Badger Capsule | G3: =IFERROR(__xludf.DUMMYFUNCTION("""COMPUTED_VALUE"""),"Series 1") -> Series 1 | H3: CHUNRI | I3: Nov 2021 | J3: 44501 | K3: 250 | L3: 250 | M3: 9 | N3: Badger Capsule | P3: =VLOOKUP(D3,'シート2'!A:B, 2, 0) -> @ChunriMD
A4: LOVENFT | B4: https://rarejapanesenfts.com/nft/lovenft/ | C4: English | D4: CHUNRI | E4: Badger Capsule>Series 1 | F4: =IFERROR(__xludf.DUMMYFUNCTION("SPLIT(E4,"">"")"),"Badger Capsule") -> Badger Capsule | G4: =IFERROR(__xludf.DUMMYFUNCTION("""COMPUTED_VALUE"""),"Series 1") -> Series 1 | H4: CHUNRI | I4: Nov 2021 | J4: 44501 | K4: 250 | L4: 250 | M4: 10 | N4: Badger Capsule | P4: =VLOOKUP(D4,'シート2'!A:B, 2, 0) -> @ChunriMD
A5: NOMOREDEFI | B5: https://rarejapanesenfts.com/nft/nomoredefi/ | C5: English | D5: BB | E5: Badger Capsule>Series 1 | F5: =IFERROR(__xludf.DUMMYFUNCTION("SPLIT(E5,"">"")"),"Badger Capsule") -> Badger Capsule | G5: =IFERROR(__xludf.DUMMYFUNCTION("""COMPUTED_VALUE"""),"Series 1") -> Series 1 | H5: BB | I5: Sep 2021 | J5: 44440 | K5: 250 | L5: 250 | M5: 2 | N5: Badger Capsule | P5: =VLOOKUP(D5,'シート2'!A:B, 2, 0) -> @MetaBB_eth
A6: HWFASHION | B6: https://rarejapanesenfts.com/nft/hwfashion/ | C6: English | D6: BB | E6: Badger Capsule>Series 1 | F6: =IFERROR(__xludf.DUMMYFUNCTION("SPLIT(E6,"">"")"),"Badger Capsule") -> Badger Capsule | G6: =IFERROR(__xludf.DUMMYFUNCTION("""COMPUTED_VALUE"""),"Series 1") -> Series 1 | H6: BB | I6: Nov 2021 | J6: 44501 | K6: 250 | L6: 250 | M6: 11 | N6: Badger Capsule | P6: =VLOOKUP(D6,'シート2'!A:B, 2, 0) -> @MetaBB_eth
A7: KAMATTE | B7: https://rarejapanesenfts.com/nft/kamatte/ | C7: English | D7: pom779 | E7: Badger Capsule>Series 1 | F7: =IFERROR(__xludf.DUMMYFUNCTION("SPLIT(E7,"">"")"),"Badger Capsule") -> Badger Capsule | G7: =IFERROR(__xludf.DUMMYFUNCTION("""COMPUTED_VALUE"""),"Series 1") -> Series 1 | H7: pom779 | I7: Oct 2021 | J7: 44470 | K7: 250 | L7: 250 | M7: 3 | N7: Badger Capsule | P7: =VLOOKUP(D7,'シート2'!A:B, 2, 0) -> @pom779
A8: FIRSTPEN | B8: https://rarejapanesenfts.com/nft/firstpen/ | C8: English | D8: くわ | E8: Badger Capsule>Badger Innovation Zone | F8: =IFERROR(__xludf.DUMMYFUNCTION("SPLIT(E8,"">"")"),"Badger Capsule") -> Badger Capsule | G8: =IFERROR(__xludf.DUMMYFUNCTION("""COMPUTED_VALUE"""),"Badger Innovation Zone") -> Badger Innovation Zone | H8: くわ | I8: Oct 2021 | J8: 44470 | K8: 500 | L8: 500 | M8: 7 | N8: Badger Capsule | P8: =VLOOKUP(D8,'シート2'!A:B, 2, 0) -> くわ
A9: HAGEPEPE | B9: https://rarejapanesenfts.com/nft/hagepepe/ | C9: English | D9: pom779 | E9: Badger Capsule>Badger Innovation Zone | F9: =IFERROR(__xludf.DUMMYFUNCTION("SPLIT(E9,"">"")"),"Badger Capsule") -> Badger Capsule | G9: =IFERROR(__xludf.DUMMYFUNCTION("""COMPUTED_VALUE"""),"Badger Innovation Zone") -> Badger Innovation Zone | H9: pom779 | I9: Oct 2021 | J9: 44470 | K9: 500 | L9: 500 | M9: 8 | N9: Badger Capsule | P9: =VLOOKUP(D9,'シート2'!A:B, 2, 0) -> @pom779
A10: KOEDAME | B10: https://rarejapanesenfts.com/nft/koedame/ | C10: English | D10: Anonymous | E10: Badger Capsule>Series 1 | F10: =IFERROR(__xludf.DUMMYFUNCTION("SPLIT(E10,"">"")"),"Badger Capsule") -> Badger Capsule | G10: =IFERROR(__xludf.DUMMYFUNCTION("""COMPUTED_VALUE"""),"Series 1") -> Series 1 | H10: Anonymous | I10: Oct 2021 | J10: 44470 | K10: 250 | L10: 250 | M10: 5 | N10: Badger Capsule | P10: =VLOOKUP(D10,'シート2'!A:B, 2, 0) -> Anonymous
A11: NOBUNSAN | B11: https://rarejapanesenfts.com/nft/nobunsan/ | C11: English | D11: nonsugar | E11: Badger Capsule>Series 1 | F11: =IFERROR(__xludf.DUMMYFUNCTION("SPLIT(E11,"">"")"),"Badger Capsule") -> Badger Capsule | G11: =IFERROR(__xludf.DUMMYFUNCTION("""COMPUTED_VALUE"""),"Series 1") -> Series 1 | H11: nonsugar | I11: Oct 2021 | J11: 44470 | K11: 250 | L11: 250 | M11: 6 | N11: Badger Capsule | P11: =VLOOKUP(D11,'シート2'!A:B, 2, 0) -> nonsugar
A12: OSHIKOMARE | B12: https://rarejapanesenfts.com/nft/oshikomare/ | C12: English | D12: ブロック男 | E12: Badger Capsule>Series 1 | F12: =IFERROR(__xludf.DUMMYFUNCTION("SPLIT(E12,"">"")"),"Badger Capsule") -> Badger Capsule | G12: =IFERROR(__xludf.DUMMYFUNCTION("""COMPUTED_VALUE"""),"Series 1") -> Series 1 | H12: ブロック男 | I12: Oct 2021 | J12: 44470 | K12: 250 | L12: 250 | M12: 4 | N12: Badger Capsule | P12: =VLOOKUP(D12,'シート2'!A:B, 2, 0) -> ブロック男
A13: NOTSOON | B13: https://rarejapanesenfts.com/nft/notsoon/ | C13: English | D13: TKY | E13: Badger Capsule>Series 1 | F13: =IFERROR(__xludf.DUMMYFUNCTION("SPLIT(E13,"">"")"),"Badger Capsule") -> Badger Capsule | G13: =IFERROR(__xludf.DUMMYFUNCTION("""COMPUTED_VALUE"""),"Series 1") -> Series 1 | H13: TKY | I13: Nov 2021 | J13: 44501 | K13: 250 | L13: 250 | M13: 13 | N13: Badger Capsule | P13: =VLOOKUP(D13,'シート2'!A:B, 2, 0) -> @Taky_Taky_
A14: SHIBACOINER | B14: https://rarejapanesenfts.com/nft/shibacoiner/ | C14: English | D14: pom779 | E14: Badger Capsule>Badger Innovation Zone | F14: =IFERROR(__xludf.DUMMYFUNCTION("SPLIT(E14,"">"")"),"Badger Capsule") -> Badger Capsule | G14: =IFERROR(__xludf.DUMMYFUNCTION("""COMPUTED_VALUE"""),"Badger Innovation Zone") -> Badger Innovation Zone | H14: pom779 | I14: Dec 2021 | J14: 44531 | K14: 500 | L14: 500 | M14: 14 | N14: Badger Capsule | P14: =VLOOKUP(D14,'シート2'!A:B, 2, 0) -> @pom779
A15: GOXGIRL | B15: https://rarejapanesenfts.com/nft/goxgirl/ | C15: English | D15: kappepe | E15: Badger Capsule>Series 1 | F15: =IFERROR(__xludf.DUMMYFUNCTION("SPLIT(E15,"">"")"),"Badger Capsule") -> Badger Capsule | G15: =IFERROR(__xludf.DUMMYFUNCTION("""COMPUTED_VALUE"""),"Series 1") -> Series 1 | H15: kappepe | I15: Dec 2021 | J15: 44531 | K15: 250 | L15: 250 | M15: 15 | N15: Badger Capsule | P15: =VLOOKUP(D15,'シート2'!A:B, 2, 0) -> @kartanbitcoin
A16: SHITTO | B16: https://rarejapanesenfts.com/nft/shitto/ | C16: English | D16: NFTuber | E16: Badger Capsule>Badger Innovation Zone | F16: =IFERROR(__xludf.DUMMYFUNCTION("SPLIT(E16,"">"")"),"Badger Capsule") -> Badger Capsule | G16: =IFERROR(__xludf.DUMMYFUNCTION("""COMPUTED_VALUE"""),"Badger Innovation Zone") -> Badger Innovation Zone | H16: NFTuber | I16: Dec 2021 | J16: 44531 | K16: 500 | L16: 500 | M16: 17 | N16: Badger Capsule | P16: =VLOOKUP(D16,'シート2'!A:B, 2, 0) -> @NFTuber
A17: DOGEMUSK | B17: https://rarejapanesenfts.com/nft/dogemusk/ | C17: English | D17: kappepe | E17: Badger Capsule>Badger Innovation Zone | F17: =IFERROR(__xludf.DUMMYFUNCTION("SPLIT(E17,"">"")"),"Badger Capsule") -> Badger Capsule | G17: =IFERROR(__xludf.DUMMYFUNCTION("""COMPUTED_VALUE"""),"Badger Innovation Zone") -> Badger Innovation Zone | H17: kappepe | I17: Dec 2021 | J17: 44531 | K17: 250 | L17: 250 | M17: 16 | N17: Badger Capsule | P17: =VLOOKUP(D17,'シート2'!A:B, 2, 0) -> @kartanbitcoin
A18: WACKNAKAMOTO | B18: https://rarejapanesenfts.com/nft/wacknakamoto/ | C18: English | D18: ごっつ | E18: Memorychain>Series 1 | F18: =IFERROR(__xludf.DUMMYFUNCTION("SPLIT(E18,"">"")"),"Memorychain") -> Memorychain | G18: =IFERROR(__xludf.DUMMYFUNCTION("""COMPUTED_VALUE"""),"Series 1") -> Series 1 | H18: ごっつ | I18: Apr 2017 | J18: 42826 | K18: 10000 | L18: 10000 | M18: 1 | N18: =F18&"🇯🇵" -> Memorychain🇯🇵 | P18: =VLOOKUP(D18,'シート2'!A:B, 2, 0) -> @nemkd12
A19: THEGODTANU | B19: https://rarejapanesenfts.com/nft/thegodtanu/ | C19: English | D19: davinci9 | E19: Memorychain>Series 1 | F19: =IFERROR(__xludf.DUMMYFUNCTION("SPLIT(E19,"">"")"),"Memorychain") -> Memorychain | G19: =IFERROR(__xludf.DUMMYFUNCTION("""COMPUTED_VALUE"""),"Series 1") -> Series 1 | H19: davinci9 | I19: Apr 2017 | J19: 42826 | K19: 100 | L19: 100 | M19: 2 | N19: =F19&"🇯🇵" -> Memorychain🇯🇵 | P19: =VLOOKUP(D19,'シート2'!A:B, 2, 0) -> @DavinciNine
A20: GOXANDTHEDAO | B20: https://rarejapanesenfts.com/nft/goxandthedao/ | C20: English | D20: davinci9 | E20: Memorychain>Series 1 | F20: =IFERROR(__xludf.DUMMYFUNCTION("SPLIT(E20,"">"")"),"Memorychain") -> Memorychain | G20: =IFERROR(__xludf.DUMMYFUNCTION("""COMPUTED_VALUE"""),"Series 1") -> Series 1 | H20: davinci9 | I20: Apr 2017 | J20: 42826 | K20: 100 | L20: 100 | M20: 3 | N20: =F20&"🇯🇵" -> Memorychain🇯🇵 | P20: =VLOOKUP(D20,'シート2'!A:B, 2, 0) -> @DavinciNine
A21: KOJITHECUPID | B21: https://rarejapanesenfts.com/nft/kojithecupid/ | C21: English | D21: AmazingJapepeneseMan | E21: Memorychain>Series 1 | F21: =IFERROR(__xludf.DUMMYFUNCTION("SPLIT(E21,"">"")"),"Memorychain") -> Memorychain | G21: =IFERROR(__xludf.DUMMYFUNCTION("""COMPUTED_VALUE"""),"Series 1") -> Series 1 | H21: AmazingJapepeneseMan | I21: Apr 2017 | J21: 42826 | K21: 777 | L21: 777 | M21: 4 | N21: =F21&"🇯🇵" -> Memorychain🇯🇵 | P21: =VLOOKUP(D21,'シート2'!A:B, 2, 0) -> @JapepeneseMan
A22: XEMURAI | B22: https://rarejapanesenfts.com/nft/xemurai/ | C22: English | D22: トレスト | E22: Memorychain>Series 1 | F22: =IFERROR(__xludf.DUMMYFUNCTION("SPLIT(E22,"">"")"),"Memorychain") -> Memorychain | G22: =IFERROR(__xludf.DUMMYFUNCTION("""COMPUTED_VALUE"""),"Series 1") -> Series 1 | H22: トレスト | I22: Apr 2017 | J22: 42826 | K22: 300 | L22: 300 | M22: 5 | N22: =F22&"🇯🇵" -> Memorychain🇯🇵 | P22: =VLOOKUP(D22,'シート2'!A:B, 2, 0) -> @TrendStream
A23: THEDAODEAD | B23: https://rarejapanesenfts.com/nft/thedaodead/ | C23: English | D23: トレスト | E23: Memorychain>Series 1 | F23: =IFERROR(__xludf.DUMMYFUNCTION("SPLIT(E23,"">"")"),"Memorychain") -> Memorychain | G23: =IFERROR(__xludf.DUMMYFUNCTION("""COMPUTED_VALUE"""),"Series 1") -> Series 1 | H23: トレスト | I23: Apr 2017 | J23: 42826 | K23: 100 | L23: 100 | M23: 6 | N23: =F23&"🇯🇵" -> Memorychain🇯🇵 | P23: =VLOOKUP(D23,'シート2'!A:B, 2, 0) -> @TrendStream
A24: BITCOINGIRL | B24: https://rarejapanesenfts.com/nft/bitcoingirl/ | C24: English | D24: 水瀬 亞里亞 | E24: Memorychain>Series 1 | F24: =IFERROR(__xludf.DUMMYFUNCTION("SPLIT(E24,"">"")"),"Memorychain") -> Memorychain | G24: =IFERROR(__xludf.DUMMYFUNCTION("""COMPUTED_VALUE"""),"Series 1") -> Series 1 | H24: 水瀬 亞里亞 | I24: Apr 2017 | J24: 42826 | K24: 1000 | L24: 1000 | M24: 7 | N24: =F24&"🇯🇵" -> Memorychain🇯🇵 | P24: =VLOOKUP(D24,'シート2'!A:B, 2, 0) -> @aria_minase
A25: MONACOINGIRL | B25: https://rarejapanesenfts.com/nft/monacoingirl/ | C25: English | D25: 水瀬 亞里亞 | E25: Memorychain>Series 1 | F25: =IFERROR(__xludf.DUMMYFUNCTION("SPLIT(E25,"">"")"),"Memorychain") -> Memorychain | G25: =IFERROR(__xludf.DUMMYFUNCTION("""COMPUTED_VALUE"""),"Series 1") -> Series 1 | H25: 水瀬 亞里亞 | I25: Apr 2017 | J25: 42826 | K25: 1000 | L25: 1000 | M25: 8 | N25: =F25&"🇯🇵" -> Memorychain🇯🇵 | P25: =VLOOKUP(D25,'シート2'!A:B, 2, 0) -> @aria_minase
A26: MINERB | B26: https://rarejapanesenfts.com/nft/minerb/ | C26: English | D26: エヌ | E26: Memorychain>Series 1 | F26: =IFERROR(__xludf.DUMMYFUNCTION("SPLIT(E26,"">"")"),"Memorychain") -> Memorychain | G26: =IFERROR(__xludf.DUMMYFUNCTION("""COMPUTED_VALUE"""),"Series 1") -> Series 1 | H26: エヌ | I26: Apr 2017 | J26: 42826 | K26: 1000 | L26: 1000 | M26: 9 | N26: =F26&"🇯🇵" -> Memorychain🇯🇵 | P26: =VLOOKUP(D26,'シート2'!A:B, 2, 0) -> @sai33211
A27: MIKEHEARNALT | B27: https://rarejapanesenfts.com/nft/mikehearnalt/ | C27: English | D27: Myon9 | E27: Memorychain>Series 1 | F27: =IFERROR(__xludf.DUMMYFUNCTION("SPLIT(E27,"">"")"),"Memorychain") -> Memorychain | G27: =IFERROR(__xludf.DUMMYFUNCTION("""COMPUTED_VALUE"""),"Series 1") -> Series 1 | H27: Myon9 | I27: Apr 2017 | J27: 42826 | K27: 317 | L27: 317 | M27: 10 | N27: =F27&"🇯🇵" -> Memorychain🇯🇵 | P27: =VLOOKUP(D27,'シート2'!A:B, 2, 0) -> @Myon9
A28: ORIGINOFMC | B28: https://rarejapanesenfts.com/nft/originofmc/ | C28: English | D28: SWINGO | E28: Memorychain>Series 1 | F28: =IFERROR(__xludf.DUMMYFUNCTION("SPLIT(E28,"">"")"),"Memorychain") -> Memorychain | G28: =IFERROR(__xludf.DUMMYFUNCTION("""COMPUTED_VALUE"""),"Series 1") -> Series 1 | H28: SWINGO | I28: Apr 2017 | J28: 42826 | K28: 100 | L28: 99 | M28: 11 | N28: =F28&"🇯🇵" -> Memorychain🇯🇵 | P28: =VLOOKUP(D28,'シート2'!A:B, 2, 0) -> @SmartSpaceDogs
A29: TOTHEMOONCD | B29: https://rarejapanesenfts.com/nft/tothemooncd/ | C29: English | D29: CHUNRI | E29: Memorychain>Series 1 | F29: =IFERROR(__xludf.DUMMYFUNCTION("SPLIT(E29,"">"")"),"Memorychain") -> Memorychain | G29: =IFERROR(__xludf.DUMMYFUNCTION("""COMPUTED_VALUE"""),"Series 1") -> Series 1 | H29: CHUNRI | I29: Apr 2017 | J29: 42826 | K29: 500 | L29: 500 | M29: 12 | N29: =F29&"🇯🇵" -> Memorychain🇯🇵 | P29: =VLOOKUP(D29,'シート2'!A:B, 2, 0) -> @ChunriMD
A30: BIGONESTEP | B30: https://rarejapanesenfts.com/nft/bigonestep/ | C30: English | D30: エヌ | E30: Memorychain>Series 1 | F30: =IFERROR(__xludf.DUMMYFUNCTION("SPLIT(E30,"">"")"),"Memorychain") -> Memorychain | G30: =IFERROR(__xludf.DUMMYFUNCTION("""COMPUTED_VALUE"""),"Series 1") -> Series 1 | H30: エヌ | I30: Apr 2017 | J30: 42826 | K30: 300 | L30: 299 | M30: 13 | N30: =F30&"🇯🇵" -> Memorychain🇯🇵 | P30: =VLOOKUP(D30,'シート2'!A:B, 2, 0) -> @sai33211
A31: XEMANDJAPAN | B31: https://rarejapanesenfts.com/nft/xemandjapan/ | C31: English | D31: 安心院まおら | E31: Memorychain>Series 1 | F31: =IFERROR(__xludf.DUMMYFUNCTION("SPLIT(E31,"">"")"),"Memorychain") -> Memorychain | G31: =IFERROR(__xludf.DUMMYFUNCTION("""COMPUTED_VALUE"""),"Series 1") -> Series 1 | H31: 安心院まおら | I31: Apr 2017 | J31: 42826 | K31: 100 | L31: 100 | M31: 14 | N31: =F31&"🇯🇵" -> Memorychain🇯🇵 | P31: =VLOOKUP(D31,'シート2'!A:B, 2, 0) -> 安心院まおら
A32: MONASEGWIT | B32: https://rarejapanesenfts.com/nft/monasegwit/ | C32: English | D32: らくがきac | E32: Memorychain>Series 1 | F32: =IFERROR(__xludf.DUMMYFUNCTION("SPLIT(E32,"">"")"),"Memorychain") -> Memorychain | G32: =IFERROR(__xludf.DUMMYFUNCTION("""COMPUTED_VALUE"""),"Series 1") -> Series 1 | H32: らくがきac | I32: Apr 2017 | J32: 42826 | K32: 100 | L32: 100 | M32: 15 | N32: =F32&"🇯🇵" -> Memorychain🇯🇵 | P32: =VLOOKUP(D32,'シート2'!A:B, 2, 0) -> @rkgk_ac
A33: THEFINTECH | B33: https://rarejapanesenfts.com/nft/thefintech/ | C33: English | D33: davinci9 | E33: Memorychain>Series 2 | F33: =IFERROR(__xludf.DUMMYFUNCTION("SPLIT(E33,"">"")"),"Memorychain") -> Memorychain | G33: =IFERROR(__xludf.DUMMYFUNCTION("""COMPUTED_VALUE"""),"Series 2") -> Series 2 | H33: davinci9 | I33: Apr 2017 | J33: 42826 | K33: 100 | L33: 100 | M33: 16 | N33: =F33&"🇯🇵" -> Memorychain🇯🇵 | P33: =VLOOKUP(D33,'シート2'!A:B, 2, 0) -> @DavinciNine
A34: QUANTUMPC | B34: https://rarejapanesenfts.com/nft/quantumpc/ | C34: English | D34: davinci9 | E34: Memorychain>Series 2 | F34: =IFERROR(__xludf.DUMMYFUNCTION("SPLIT(E34,"">"")"),"Memorychain") -> Memorychain | G34: =IFERROR(__xludf.DUMMYFUNCTION("""COMPUTED_VALUE"""),"Series 2") -> Series 2 | H34: davinci9 | I34: Apr 2017 | J34: 42826 | K34: 100 | L34: 100 | M34: 17 | N34: =F34&"🇯🇵" -> Memorychain🇯🇵 | P34: =VLOOKUP(D34,'シート2'!A:B, 2, 0) -> @DavinciNine
A35: MONEROGIRL | B35: https://rarejapanesenfts.com/nft/monerogirl/ | C35: English | D35: 水瀬 亞里亞 | E35: Memorychain>Series 2 | F35: =IFERROR(__xludf.DUMMYFUNCTION("SPLIT(E35,"">"")"),"Memorychain") -> Memorychain | G35: =IFERROR(__xludf.DUMMYFUNCTION("""COMPUTED_VALUE"""),"Series 2") -> Series 2 | H35: 水瀬 亞里亞 | I35: Apr 2017 | J35: 42826 | K35: 1000 | L35: 1000 | M35: 18 | N35: =F35&"🇯🇵" -> Memorychain🇯🇵 | P35: =VLOOKUP(D35,'シート2'!A:B, 2, 0) -> @aria_minase
A36: ETHEREUMGIRL | B36: https://rarejapanesenfts.com/nft/ethereumgirl/ | C36: English | D36: 水瀬 亞里亞 | E36: Memorychain>Series 2 | F36: =IFERROR(__xludf.DUMMYFUNCTION("SPLIT(E36,"">"")"),"Memorychain") -> Memorychain | G36: =IFERROR(__xludf.DUMMYFUNCTION("""COMPUTED_VALUE"""),"Series 2") -> Series 2 | H36: 水瀬 亞里亞 | I36: Apr 2017 | J36: 42826 | K36: 1000 | L36: 1000 | M36: 19 | N36: =F36&"🇯🇵" -> Memorychain🇯🇵 | P36: =VLOOKUP(D36,'シート2'!A:B, 2, 0) -> @aria_minase
A37: RIPPLEGIRL | B37: https://rarejapanesenfts.com/nft/ripplegirl/ | C37: English | D37: 水瀬 亞里亞 | E37: Memorychain>Series 2 | F37: =IFERROR(__xludf.DUMMYFUNCTION("SPLIT(E37,"">"")"),"Memorychain") -> Memorychain | G37: =IFERROR(__xludf.DUMMYFUNCTION("""COMPUTED_VALUE"""),"Series 2") -> Series 2 | H37: 水瀬 亞里亞 | I37: Apr 2017 | J37: 42826 | K37: 1000 | L37: 1000 | M37: 20 | N37: =F37&"🇯🇵" -> Memorychain🇯🇵 | P37: =VLOOKUP(D37,'シート2'!A:B, 2, 0) -> @aria_minase
A38: XASICBOOST | B38: https://rarejapanesenfts.com/nft/xasicboost/ | C38: English | D38: SWINGO | E38: Memorychain>Series 2 | F38: =IFERROR(__xludf.DUMMYFUNCTION("SPLIT(E38,"">"")"),"Memorychain") -> Memorychain | G38: =IFERROR(__xludf.DUMMYFUNCTION("""COMPUTED_VALUE"""),"Series 2") -> Series 2 | H38: SWINGO | I38: Apr 2017 | J38: 42826 | K38: 100 | L38: 100 | M38: 21 | N38: =F38&"🇯🇵" -> Memorychain🇯🇵 | P38: =VLOOKUP(D38,'シート2'!A:B, 2, 0) -> @SmartSpaceDogs
A39: REJECTEDVIX | B39: https://rarejapanesenfts.com/nft/rejectedvix/ | C39: English | D39: Myon9 | E39: Memorychain>Series 2 | F39: =IFERROR(__xludf.DUMMYFUNCTION("SPLIT(E39,"">"")"),"Memorychain") -> Memorychain | G39: =IFERROR(__xludf.DUMMYFUNCTION("""COMPUTED_VALUE"""),"Series 2") -> Series 2 | H39: Myon9 | I39: Apr 2017 | J39: 42826 | K39: 700 | L39: 700 | M39: 22 | N39: =F39&"🇯🇵" -> Memorychain🇯🇵 | P39: =VLOOKUP(D39,'シート2'!A:B, 2, 0) -> @Myon9
A40: RAMENSOG | B40: https://rarejapanesenfts.com/nft/ramensog/ | C40: English | D40: Kassy | E40: Memorychain>Series 2 | F40: =IFERROR(__xludf.DUMMYFUNCTION("SPLIT(E40,"">"")"),"Memorychain") -> Memorychain | G40: =IFERROR(__xludf.DUMMYFUNCTION("""COMPUTED_VALUE"""),"Series 2") -> Series 2 | H40: Kassy | I40: Apr 2017 | J40: 42826 | K40: 150 | L40: 149 | M40: 23 | N40: =F40&"🇯🇵" -> Memorychain🇯🇵 | P40: =VLOOKUP(D40,'シート2'!A:B, 2, 0) -> @kassy_nara
...

Sheet シート2
A1: Artists | D1: Twitter
A2: ごっつ | B2: @nemkd12 | D2: https://twitter.com/nemkd12
A3: Koji | B3: @Coin_and_Peace | D3: https://twitter.com/Coin_and_Peace
A4: kappepe | B4: @kartanbitcoin | D4: https://twitter.com/kartanbitcoin
A5: CHUNRI | B5: @ChunriMD | D5: https://twitter.com/ChunriMD
A6: BB | B6: @MetaBB_eth | D6: https://twitter.com/MetaBB_eth
A7: くわ | B7: くわ
A8: pom779 | B8: @pom779 | D8: https://twitter.com/pom779
A9: Anonymous | B9: Anonymous
A10: nonsugar | B10: nonsugar
A11: ブロック男 | B11: ブロック男
A12: TKY | B12: @Taky_Taky_ | D12: https://twitter.com/Taky_Taky_
A13: NFTuber | B13: @NFTuber | D13: https://twitter.com/NFTuber
A14: davinci9 | B14: @DavinciNine | D14: https://twitter.com/DavinciNine
A15: AmazingJapepeneseMan | B15: @JapepeneseMan | D15: https://twitter.com/JapepeneseMan
A16: トレスト | B16: @TrendStream | D16: https://twitter.com/TrendStream
A17: 水瀬 亞里亞 | B17: @aria_minase | D17: https://mobile.twitter.com/aria_minase
A18: エヌ | B18: @sai33211 | D18: https://twitter.com/sai33211
A19: Myon9 | B19: @Myon9 | D19: https://twitter.com/Myon9
A20: SWINGO | B20: @SmartSpaceDogs | D20: https://twitter.com/SmartSpaceDogs
A21: 安心院まおら | B21: 安心院まおら
A22: らくがきac | B22: @rkgk_ac | D22: https://twitter.com/rkgk_ac
A23: Kassy | B23: @kassy_nara | D23: https://twitter.com/kassy_nara
A24: ミツコア | B24: @mizcored | D24: https://twitter.com/mizcored
A25: たろふあ | B25: たろふあ
A26: VeryLongUnagi | B26: VeryLongUnagi
A27: 笑猫 | B27: @1aughingcat | D27: https://twitter.com/1aughingcat
A28: 裏技君 | B28: @urawazakun | D28: https://twitter.com/urawazakun
A29: 響 | B29: @Whiskey_bonbon_ | D29: https://twitter.com/Whiskey_bonbon_
A30: 藤堂竜白 | B30: @todokasumi | D30: https://twitter.com/todokasumi
A31: x0xb0x | B31: @x0xb0x1 | D31: https://twitter.com/x0xb0x1
A32: べた | B32: @ethereumon | D32: https://twitter.com/ethereumon
A33: PJ | B33: PJ
A34: メルキャット | B34: メルキャット
A35: 栗饅頭 | B35: 栗饅頭
A36: 五所川原銭夫 | B36: 五所川原銭夫
A37: 睡眠 | B37: 睡眠
A38: Onigiri | B38: @7cryptocurrency | D38: https://twitter.com/7cryptocurrency
A39: チノ | B39: チノ
A40: M1XXK1NG W1CKED | B40: M1XXK1NG W1CKED
...

Sheet NFTs-Export-2022-September-05-1
A1: Title | B1: Permalink | C1: Languages | D1: Artists | E1: collections&Series | F1: collections | G1: Series | H1: artist_name | I1: issued | J1: issued_ja | K1: total_supply | L1: real_supply | M1: card_num
A2: PEPEBAZAAR | B2: https://rarejapanesenfts.com/nft/pepebazaar/ | C2: English | D2: kappepe | E2: Badger Capsule>Series 1 | F2: =IFERROR(__xludf.DUMMYFUNCTION("SPLIT(E2,"">"")"),"Badger Capsule") -> Badger Capsule | G2: =IFERROR(__xludf.DUMMYFUNCTION("""COMPUTED_VALUE"""),"Series 1") -> Series 1 | H2: kappepe | I2: Nov 2021 | J2: 44501 | K2: 250 | L2: 250 | M2: 12
A3: IDOJAWAN | B3: https://rarejapanesenfts.com/nft/idojawan/ | C3: English | D3: CHUNRI | E3: Badger Capsule>Series 1 | F3: =IFERROR(__xludf.DUMMYFUNCTION("SPLIT(E3,"">"")"),"Badger Capsule") -> Badger Capsule | G3: =IFERROR(__xludf.DUMMYFUNCTION("""COMPUTED_VALUE"""),"Series 1") -> Series 1 | H3: CHUNRI | I3: Nov 2021 | J3: 44501 | K3: 250 | L3: 250 | M3: 9
A4: LOVENFT | B4: https://rarejapanesenfts.com/nft/lovenft/ | C4: English | D4: CHUNRI | E4: Badger Capsule>Series 1 | F4: =IFERROR(__xludf.DUMMYFUNCTION("SPLIT(E4,"">"")"),"Badger Capsule") -> Badger Capsule | G4: =IFERROR(__xludf.DUMMYFUNCTION("""COMPUTED_VALUE"""),"Series 1") -> Series 1 | H4: CHUNRI | I4: Nov 2021 | J4: 44501 | K4: 250 | L4: 250 | M4: 10
A5: NOMOREDEFI | B5: https://rarejapanesenfts.com/nft/nomoredefi/ | C5: English | D5: BB | E5: Badger Capsule>Series 1 | F5: =IFERROR(__xludf.DUMMYFUNCTION("SPLIT(E5,"">"")"),"Badger Capsule") -> Badger Capsule | G5: =IFERROR(__xludf.DUMMYFUNCTION("""COMPUTED_VALUE"""),"Series 1") -> Series 1 | H5: BB | I5: Sep 2021 | J5: 44440 | K5: 250 | L5: 250 | M5: 2
A6: HWFASHION | B6: https://rarejapanesenfts.com/nft/hwfashion/ | C6: English | D6: BB | E6: Badger Capsule>Series 1 | F6: =IFERROR(__xludf.DUMMYFUNCTION("SPLIT(E6,"">"")"),"Badger Capsule") -> Badger Capsule | G6: =IFERROR(__xludf.DUMMYFUNCTION("""COMPUTED_VALUE"""),"Series 1") -> Series 1 | H6: BB | I6: Nov 2021 | J6: 44501 | K6: 250 | L6: 250 | M6: 11
A7: KAMATTE | B7: https://rarejapanesenfts.com/nft/kamatte/ | C7: English | D7: pom779 | E7: Badger Capsule>Series 1 | F7: =IFERROR(__xludf.DUMMYFUNCTION("SPLIT(E7,"">"")"),"Badger Capsule") -> Badger Capsule | G7: =IFERROR(__xludf.DUMMYFUNCTION("""COMPUTED_VALUE"""),"Series 1") -> Series 1 | H7: pom779 | I7: Oct 2021 | J7: 44470 | K7: 250 | L7: 250 | M7: 3
A8: FIRSTPEN | B8: https://rarejapanesenfts.com/nft/firstpen/ | C8: English | D8: くわ | E8: Badger Capsule>Badger Innovation Zone | F8: =IFERROR(__xludf.DUMMYFUNCTION("SPLIT(E8,"">"")"),"Badger Capsule") -> Badger Capsule | G8: =IFERROR(__xludf.DUMMYFUNCTION("""COMPUTED_VALUE"""),"Badger Innovation Zone") -> Badger Innovation Zone | H8: くわ | I8: Oct 2021 | J8: 44470 | K8: 500 | L8: 500 | M8: 7
A9: HAGEPEPE | B9: https://rarejapanesenfts.com/nft/hagepepe/ | C9: English | D9: pom779 | E9: Badger Capsule>Badger Innovation Zone | F9: =IFERROR(__xludf.DUMMYFUNCTION("SPLIT(E9,"">"")"),"Badger Capsule") -> Badger Capsule | G9: =IFERROR(__xludf.DUMMYFUNCTION("""COMPUTED_VALUE"""),"Badger Innovation Zone") -> Badger Innovation Zone | H9: pom779 | I9: Oct 2021 | J9: 44470 | K9: 500 | L9: 500 | M9: 8
A10: KOEDAME | B10: https://rarejapanesenfts.com/nft/koedame/ | C10: English | D10: Anonymous | E10: Badger Capsule>Series 1 | F10: =IFERROR(__xludf.DUMMYFUNCTION("SPLIT(E10,"">"")"),"Badger Capsule") -> Badger Capsule | G10: =IFERROR(__xludf.DUMMYFUNCTION("""COMPUTED_VALUE"""),"Series 1") -> Series 1 | H10: Anonymous | I10: Oct 2021 | J10: 44470 | K10: 250 | L10: 250 | M10: 5
A11: NOBUNSAN | B11: https://rarejapanesenfts.com/nft/nobunsan/ | C11: English | D11: nonsugar | E11: Badger Capsule>Series 1 | F11: =IFERROR(__xludf.DUMMYFUNCTION("SPLIT(E11,"">"")"),"Badger Capsule") -> Badger Capsule | G11: =IFERROR(__xludf.DUMMYFUNCTION("""COMPUTED_VALUE"""),"Series 1") -> Series 1 | H11: nonsugar | I11: Oct 2021 | J11: 44470 | K11: 250 | L11: 250 | M11: 6
A12: OSHIKOMARE | B12: https://rarejapanesenfts.com/nft/oshikomare/ | C12: English | D12: ブロック男 | E12: Badger Capsule>Series 1 | F12: =IFERROR(__xludf.DUMMYFUNCTION("SPLIT(E12,"">"")"),"Badger Capsule") -> Badger Capsule | G12: =IFERROR(__xludf.DUMMYFUNCTION("""COMPUTED_VALUE"""),"Series 1") -> Series 1 | H12: ブロック男 | I12: Oct 2021 | J12: 44470 | K12: 250 | L12: 250 | M12: 4
A13: NOTSOON | B13: https://rarejapanesenfts.com/nft/notsoon/ | C13: English | D13: TKY | E13: Badger Capsule>Series 1 | F13: =IFERROR(__xludf.DUMMYFUNCTION("SPLIT(E13,"">"")"),"Badger Capsule") -> Badger Capsule | G13: =IFERROR(__xludf.DUMMYFUNCTION("""COMPUTED_VALUE"""),"Series 1") -> Series 1 | H13: TKY | I13: Nov 2021 | J13: 44501 | K13: 250 | L13: 250 | M13: 13
A14: SHIBACOINER | B14: https://rarejapanesenfts.com/nft/shibacoiner/ | C14: English | D14: pom779 | E14: Badger Capsule>Badger Innovation Zone | F14: =IFERROR(__xludf.DUMMYFUNCTION("SPLIT(E14,"">"")"),"Badger Capsule") -> Badger Capsule | G14: =IFERROR(__xludf.DUMMYFUNCTION("""COMPUTED_VALUE"""),"Badger Innovation Zone") -> Badger Innovation Zone | H14: pom779 | I14: Dec 2021 | J14: 44531 | K14: 500 | L14: 500 | M14: 14
A15: GOXGIRL | B15: https://rarejapanesenfts.com/nft/goxgirl/ | C15: English | D15: kappepe | E15: Badger Capsule>Series 1 | F15: =IFERROR(__xludf.DUMMYFUNCTION("SPLIT(E15,"">"")"),"Badger Capsule") -> Badger Capsule | G15: =IFERROR(__xludf.DUMMYFUNCTION("""COMPUTED_VALUE"""),"Series 1") -> Series 1 | H15: kappepe | I15: Dec 2021 | J15: 44531 | K15: 250 | L15: 250 | M15: 15
A16: SHITTO | B16: https://rarejapanesenfts.com/nft/shitto/ | C16: English | D16: NFTuber | E16: Badger Capsule>Badger Innovation Zone | F16: =IFERROR(__xludf.DUMMYFUNCTION("SPLIT(E16,"">"")"),"Badger Capsule") -> Badger Capsule | G16: =IFERROR(__xludf.DUMMYFUNCTION("""COMPUTED_VALUE"""),"Badger Innovation Zone") -> Badger Innovation Zone | H16: NFTuber | I16: Dec 2021 | J16: 44531 | K16: 500 | L16: 500 | M16: 17
A17: DOGEMUSK | B17: https://rarejapanesenfts.com/nft/dogemusk/ | C17: English | D17: kappepe | E17: Badger Capsule>Badger Innovation Zone | F17: =IFERROR(__xludf.DUMMYFUNCTION("SPLIT(E17,"">"")"),"Badger Capsule") -> Badger Capsule | G17: =IFERROR(__xludf.DUMMYFUNCTION("""COMPUTED_VALUE"""),"Badger Innovation Zone") -> Badger Innovation Zone | H17: kappepe | I17: Dec 2021 | J17: 44531 | K17: 250 | L17: 250 | M17: 16
A18: WACKNAKAMOTO | B18: https://rarejapanesenfts.com/nft/wacknakamoto/ | C18: English | D18: ごっつ | E18: Memorychain>Series 1 | F18: =IFERROR(__xludf.DUMMYFUNCTION("SPLIT(E18,"">"")"),"Memorychain") -> Memorychain | G18: =IFERROR(__xludf.DUMMYFUNCTION("""COMPUTED_VALUE"""),"Series 1") -> Series 1 | H18: ごっつ | I18: Apr 2017 | J18: 42826 | K18: 10000 | L18: 10000 | M18: 1
A19: THEGODTANU | B19: https://rarejapanesenfts.com/nft/thegodtanu/ | C19: English | D19: davinci9 | E19: Memorychain>Series 1 | F19: =IFERROR(__xludf.DUMMYFUNCTION("SPLIT(E19,"">"")"),"Memorychain") -> Memorychain | G19: =IFERROR(__xludf.DUMMYFUNCTION("""COMPUTED_VALUE"""),"Series 1") -> Series 1 | H19: davinci9 | I19: Apr 2017 | J19: 42826 | K19: 100 | L19: 100 | M19: 2
A20: GOXANDTHEDAO | B20: https://rarejapanesenfts.com/nft/goxandthedao/ | C20: English | D20: davinci9 | E20: Memorychain>Series 1 | F20: =IFERROR(__xludf.DUMMYFUNCTION("SPLIT(E20,"">"")"),"Memorychain") -> Memorychain | G20: =IFERROR(__xludf.DUMMYFUNCTION("""COMPUTED_VALUE"""),"Series 1") -> Series 1 | H20: davinci9 | I20: Apr 2017 | J20: 42826 | K20: 100 | L20: 100 | M20: 3
A21: KOJITHECUPID | B21: https://rarejapanesenfts.com/nft/kojithecupid/ | C21: English | D21: AmazingJapepeneseMan | E21: Memorychain>Series 1 | F21: =IFERROR(__xludf.DUMMYFUNCTION("SPLIT(E21,"">"")"),"Memorychain") -> Memorychain | G21: =IFERROR(__xludf.DUMMYFUNCTION("""COMPUTED_VALUE"""),"Series 1") -> Series 1 | H21: AmazingJapepeneseMan | I21: Apr 2017 | J21: 42826 | K21: 777 | L21: 777 | M21: 4
A22: XEMURAI | B22: https://rarejapanesenfts.com/nft/xemurai/ | C22: English | D22: トレスト | E22: Memorychain>Series 1 | F22: =IFERROR(__xludf.DUMMYFUNCTION("SPLIT(E22,"">"")"),"Memorychain") -> Memorychain | G22: =IFERROR(__xludf.DUMMYFUNCTION("""COMPUTED_VALUE"""),"Series 1") -> Series 1 | H22: トレスト | I22: Apr 2017 | J22: 42826 | K22: 300 | L22: 300 | M22: 5
A23: THEDAODEAD | B23: https://rarejapanesenfts.com/nft/thedaodead/ | C23: English | D23: トレスト | E23: Memorychain>Series 1 | F23: =IFERROR(__xludf.DUMMYFUNCTION("SPLIT(E23,"">"")"),"Memorychain") -> Memorychain | G23: =IFERROR(__xludf.DUMMYFUNCTION("""COMPUTED_VALUE"""),"Series 1") -> Series 1 | H23: トレスト | I23: Apr 2017 | J23: 42826 | K23: 100 | L23: 100 | M23: 6
A24: BITCOINGIRL | B24: https://rarejapanesenfts.com/nft/bitcoingirl/ | C24: English | D24: 水瀬 亞里亞 | E24: Memorychain>Series 1 | F24: =IFERROR(__xludf.DUMMYFUNCTION("SPLIT(E24,"">"")"),"Memorychain") -> Memorychain | G24: =IFERROR(__xludf.DUMMYFUNCTION("""COMPUTED_VALUE"""),"Series 1") -> Series 1 | H24: 水瀬 亞里亞 | I24: Apr 2017 | J24: 42826 | K24: 1000 | L24: 1000 | M24: 7
A25: MONACOINGIRL | B25: https://rarejapanesenfts.com/nft/monacoingirl/ | C25: English | D25: 水瀬 亞里亞 | E25: Memorychain>Series 1 | F25: =IFERROR(__xludf.DUMMYFUNCTION("SPLIT(E25,"">"")"),"Memorychain") -> Memorychain | G25: =IFERROR(__xludf.DUMMYFUNCTION("""COMPUTED_VALUE"""),"Series 1") -> Series 1 | H25: 水瀬 亞里亞 | I25: Apr 2017 | J25: 42826 | K25: 1000 | L25: 1000 | M25: 8
A26: MINERB | B26: https://rarejapanesenfts.com/nft/minerb/ | C26: English | D26: エヌ | E26: Memorychain>Series 1 | F26: =IFERROR(__xludf.DUMMYFUNCTION("SPLIT(E26,"">"")"),"Memorychain") -> Memorychain | G26: =IFERROR(__xludf.DUMMYFUNCTION("""COMPUTED_VALUE"""),"Series 1") -> Series 1 | H26: エヌ | I26: Apr 2017 | J26: 42826 | K26: 1000 | L26: 1000 | M26: 9
A27: MIKEHEARNALT | B27: https://rarejapanesenfts.com/nft/mikehearnalt/ | C27: English | D27: Myon9 | E27: Memorychain>Series 1 | F27: =IFERROR(__xludf.DUMMYFUNCTION("SPLIT(E27,"">"")"),"Memorychain") -> Memorychain | G27: =IFERROR(__xludf.DUMMYFUNCTION("""COMPUTED_VALUE"""),"Series 1") -> Series 1 | H27: Myon9 | I27: Apr 2017 | J27: 42826 | K27: 317 | L27: 317 | M27: 10
A28: ORIGINOFMC | B28: https://rarejapanesenfts.com/nft/originofmc/ | C28: English | D28: SWINGO | E28: Memorychain>Series 1 | F28: =IFERROR(__xludf.DUMMYFUNCTION("SPLIT(E28,"">"")"),"Memorychain") -> Memorychain | G28: =IFERROR(__xludf.DUMMYFUNCTION("""COMPUTED_VALUE"""),"Series 1") -> Series 1 | H28: SWINGO | I28: Apr 2017 | J28: 42826 | K28: 100 | L28: 99 | M28: 11
A29: TOTHEMOONCD | B29: https://rarejapanesenfts.com/nft/tothemooncd/ | C29: English | D29: CHUNRI | E29: Memorychain>Series 1 | F29: =IFERROR(__xludf.DUMMYFUNCTION("SPLIT(E29,"">"")"),"Memorychain") -> Memorychain | G29: =IFERROR(__xludf.DUMMYFUNCTION("""COMPUTED_VALUE"""),"Series 1") -> Series 1 | H29: CHUNRI | I29: Apr 2017 | J29: 42826 | K29: 500 | L29: 500 | M29: 12
A30: BIGONESTEP | B30: https://rarejapanesenfts.com/nft/bigonestep/ | C30: English | D30: エヌ | E30: Memorychain>Series 1 | F30: =IFERROR(__xludf.DUMMYFUNCTION("SPLIT(E30,"">"")"),"Memorychain") -> Memorychain | G30: =IFERROR(__xludf.DUMMYFUNCTION("""COMPUTED_VALUE"""),"Series 1") -> Series 1 | H30: エヌ | I30: Apr 2017 | J30: 42826 | K30: 300 | L30: 299 | M30: 13
A31: XEMANDJAPAN | B31: https://rarejapanesenfts.com/nft/xemandjapan/ | C31: English | D31: 安心院まおら | E31: Memorychain>Series 1 | F31: =IFERROR(__xludf.DUMMYFUNCTION("SPLIT(E31,"">"")"),"Memorychain") -> Memorychain | G31: =IFERROR(__xludf.DUMMYFUNCTION("""COMPUTED_VALUE"""),"Series 1") -> Series 1 | H31: 安心院まおら | I31: Apr 2017 | J31: 42826 | K31: 100 | L31: 100 | M31: 14
A32: MONASEGWIT | B32: https://rarejapanesenfts.com/nft/monasegwit/ | C32: English | D32: らくがきac | E32: Memorychain>Series 1 | F32: =IFERROR(__xludf.DUMMYFUNCTION("SPLIT(E32,"">"")"),"Memorychain") -> Memorychain | G32: =IFERROR(__xludf.DUMMYFUNCTION("""COMPUTED_VALUE"""),"Series 1") -> Series 1 | H32: らくがきac | I32: Apr 2017 | J32: 42826 | K32: 100 | L32: 100 | M32: 15
A33: THEFINTECH | B33: https://rarejapanesenfts.com/nft/thefintech/ | C33: English | D33: davinci9 | E33: Memorychain>Series 2 | F33: =IFERROR(__xludf.DUMMYFUNCTION("SPLIT(E33,"">"")"),"Memorychain") -> Memorychain | G33: =IFERROR(__xludf.DUMMYFUNCTION("""COMPUTED_VALUE"""),"Series 2") -> Series 2 | H33: davinci9 | I33: Apr 2017 | J33: 42826 | K33: 100 | L33: 100 | M33: 16
A34: QUANTUMPC | B34: https://rarejapanesenfts.com/nft/quantumpc/ | C34: English | D34: davinci9 | E34: Memorychain>Series 2 | F34: =IFERROR(__xludf.DUMMYFUNCTION("SPLIT(E34,"">"")"),"Memorychain") -> Memorychain | G34: =IFERROR(__xludf.DUMMYFUNCTION("""COMPUTED_VALUE"""),"Series 2") -> Series 2 | H34: davinci9 | I34: Apr 2017 | J34: 42826 | K34: 100 | L34: 100 | M34: 17
A35: MONEROGIRL | B35: https://rarejapanesenfts.com/nft/monerogirl/ | C35: English | D35: 水瀬 亞里亞 | E35: Memorychain>Series 2 | F35: =IFERROR(__xludf.DUMMYFUNCTION("SPLIT(E35,"">"")"),"Memorychain") -> Memorychain | G35: =IFERROR(__xludf.DUMMYFUNCTION("""COMPUTED_VALUE"""),"Series 2") -> Series 2 | H35: 水瀬 亞里亞 | I35: Apr 2017 | J35: 42826 | K35: 1000 | L35: 1000 | M35: 18
A36: ETHEREUMGIRL | B36: https://rarejapanesenfts.com/nft/ethereumgirl/ | C36: English | D36: 水瀬 亞里亞 | E36: Memorychain>Series 2 | F36: =IFERROR(__xludf.DUMMYFUNCTION("SPLIT(E36,"">"")"),"Memorychain") -> Memorychain | G36: =IFERROR(__xludf.DUMMYFUNCTION("""COMPUTED_VALUE"""),"Series 2") -> Series 2 | H36: 水瀬 亞里亞 | I36: Apr 2017 | J36: 42826 | K36: 1000 | L36: 1000 | M36: 19
A37: RIPPLEGIRL | B37: https://rarejapanesenfts.com/nft/ripplegirl/ | C37: English | D37: 水瀬 亞里亞 | E37: Memorychain>Series 2 | F37: =IFERROR(__xludf.DUMMYFUNCTION("SPLIT(E37,"">"")"),"Memorychain") -> Memorychain | G37: =IFERROR(__xludf.DUMMYFUNCTION("""COMPUTED_VALUE"""),"Series 2") -> Series 2 | H37: 水瀬 亞里亞 | I37: Apr 2017 | J37: 42826 | K37: 1000 | L37: 1000 | M37: 20
A38: XASICBOOST | B38: https://rarejapanesenfts.com/nft/xasicboost/ | C38: English | D38: SWINGO | E38: Memorychain>Series 2 | F38: =IFERROR(__xludf.DUMMYFUNCTION("SPLIT(E38,"">"")"),"Memorychain") -> Memorychain | G38: =IFERROR(__xludf.DUMMYFUNCTION("""COMPUTED_VALUE"""),"Series 2") -> Series 2 | H38: SWINGO | I38: Apr 2017 | J38: 42826 | K38: 100 | L38: 100 | M38: 21
A39: REJECTEDVIX | B39: https://rarejapanesenfts.com/nft/rejectedvix/ | C39: English | D39: Myon9 | E39: Memorychain>Series 2 | F39: =IFERROR(__xludf.DUMMYFUNCTION("SPLIT(E39,"">"")"),"Memorychain") -> Memorychain | G39: =IFERROR(__xludf.DUMMYFUNCTION("""COMPUTED_VALUE"""),"Series 2") -> Series 2 | H39: Myon9 | I39: Apr 2017 | J39: 42826 | K39: 700 | L39: 700 | M39: 22
A40: RAMENSOG | B40: https://rarejapanesenfts.com/nft/ramensog/ | C40: English | D40: Kassy | E40: Memorychain>Series 2 | F40: =IFERROR(__xludf.DUMMYFUNCTION("SPLIT(E40,"">"")"),"Memorychain") -> Memorychain | G40: =IFERROR(__xludf.DUMMYFUNCTION("""COMPUTED_VALUE"""),"Series 2") -> Series 2 | H40: Kassy | I40: Apr 2017 | J40: 42826 | K40: 150 | L40: 149 | M40: 23
...

Sheet 220526～追加分 の20220906コピー
A1: データ未入力or修正必要 | B1: Artists | C1: Twitter | D1: Opensea | E1: CPアドレス | F1: Website | G1: アーティスト紹介文（外注し、英訳する予定です。） | H1: その他何かあれば
A2: FALSE | B2: ごっつ | C2: https://twitter.com/nemkd12 | E2: https://xchain.io/address/15MDXC3YkR5sHL34c41YMonkxJP7RKeLK1 | F2: https://dhpkww12.hatenablog.com/archive | G2: 2016年ごろRAREPEPEやBitGirlsの存在を知り、Counterpartyトークン、いわゆるビンテージNFTを用いた活動を楽しんでいました。中でも、Memorychainでの思い出は深く、WACKシリーズ3作品を作成、たくさんの作品をコレクションしていました。2017年～2018年までは、Spells of Genesisの日本語翻訳、コミュニティマネジメントといったお手伝いもしていました。 | H2: 特定のカードを売る気がない、秘密鍵が紛失した、アーティスト名を変更したいなど。 ーーーー サイトに下記の4項目を設定・表示させる予定です。 作者アクティブ：作者は秘密鍵をまだ保有し、売買可能 作者非アクティブ：作者は長期間動きがなく、秘密鍵を失った可能性もある 運営アクティブ：運営会社が活発に売買している 運営非アクティブ：運営会社は積極的に売買をしていない（将来的に配布されたり、市場で売りに出される可能性がある）
A3: FALSE | B3: Koji | C3: https://twitter.com/Coin_and_Peace | E3: 1BRB38LNN1CNWeQngKeeZFF7osBpmyieKa 1Q2Vgxpvx6L9nf9evy2FHjAZWKG2J3TuaQ | F3: https://kojihigashi.info | G3: メモチェンドリームを実現させたい人です
A4: FALSE | B4: kappepe | C4: https://twitter.com/kartanbitcoin | E4: 1E3kn4VBfAsjamEpq84o6WVUwno2B2nRBu | G4: メモチェン・オアシスマイニング・レアぺぺで、３名のクリエーターをサポートしました。 ごめんなさい。わたし自身は一切絵心ありません。 takaraでメモチェンカードを落としたり拾ったりしてた頃が一番楽しかったです。 takara帰ってこないかな。
A5: FALSE | B5: CHUNRI | C5: https://twitter.com/ChunriMD | E5: 1AanCo9CJSomhUEy2YrhfXrU1PboBhFaBq | G5: 仮想通貨に出会い,RAREPEPEと出会い、落書き画力を駆使してNFTアーティストとして活動中。 2018年当時からPEPECASHWATCH（腕時計）を作成し ChunriPEPE（RAREPEPEカード）とセットで仮想通貨を使った販売するなど、現物商品と仮想通貨をつなげる活動も行っていた。 XCPトークンをベースとするNFTアート製作を中心に活動を続けていきます。
A6: FALSE | B6: BB | C6: https://twitter.com/MetaBB_eth | D6: https://opensea.io/BBSea | E6: 1AoAkpQo7p2jSAW5raa3MbUtXqvFq3SRvU
A7: FALSE | B7: くわ
A8: FALSE | B8: pom779 | C8: https://twitter.com/pom779 | D8: https://opensea.io/Pom779 | E8: 1A3iBZcfzUvMUXo7LZExMLApgkRacpfXms | G8: 私はモナカードアーティストです。2017年にビットコインに注目し、その後すぐRAREPEPEやMemorychainを見つけました。当時はそれらのたくさんのカードを眺めながら、世界で何が起こっているのかよく分からない！と思いました。そして今は常識的な社会から見たら狂気のクリプト界で出来事をイラストにしています。今回はBadger Cupsule Cardの企画でMemorychainアーティストの人達と一緒に活動できてとても嬉しいです。 | H8: 私は作品がBadger capsuleシリーズのみですが、「作者アクティブ」状態です。
A9: FALSE | B9: Anonymous | G9: 匿名アーティスト達
A10: FALSE | B10: nonsugar
A11: FALSE | B11: ブロック男
A12: FALSE | B12: TKY | C12: https://twitter.com/Taky_Taky_ | D12: https://opensea.io/TKY | E12: 16xG9NoSKAbMhbAgnwhMv2iDx8RY9cf87X | F12: instagram.com/tky_nft | G12: 2016年からの暗号資産民です。好きな言葉はメモチェンドリームです。
A13: FALSE | B13: NFTuber | C13: https://twitter.com/NFTuber | D13: https://opensea.io/NFTuberRecoveryAccount | E13: 1HvhqnWsHnSijTSLRKVH79QEMDtiuExZYh | F13: https://nftuber.com/ | G13: Memorychainの世界観が大好きで、アニメ系キャラをこよなく愛してます。OTAKUの一番上の兄と一緒に各国アーティストの方々と遊んでいます。作品を交換する文化も大好きです♪
A14: FALSE | B14: davinci9 | C14: https://twitter.com/DavinciNine | E14: 1GNQdAkP1zEToHbtZjqaQwqMU6Eg6Xu4Um
A15: FALSE | B15: AmazingJapepeneseMan | C15: https://twitter.com/JapepeneseMan | E15: 1Q2Vgxpvx6L9nf9evy2FHjAZWKG2J3TuaQ
A16: FALSE | B16: トレスト | C16: https://twitter.com/TrendStream | E16: 13L4Jd92Mb8YwPCreEkjV422aWaZDVdkrQ
A17: FALSE | B17: 水瀬 亞里亞 | C17: https://mobile.twitter.com/aria_minase | E17: 12T6iEDNc42L9W8kgtDVBFMQo4JAdUKAkT
A18: FALSE | B18: エヌ | C18: https://twitter.com/sai33211 | D18: https://opensea.io/sai33211 | E18: 187ToQV2FDTLbgiFKr2mxBm29qzEDPuo6P | G18: 2016～2017年頃からRarepepeやMemorychainの製作活動をしていました。カードを集めたりもしてます。今は、メタバースのために3DNFTを模索中です。Soon...
A19: FALSE | B19: Myon9 | C19: https://twitter.com/Myon9 | E19: 15DyT6GU5bwViSwhtKu7fGb1JGv5gdK5iL | G19: モナコイナー|エンジョイ勢|基本ゲームばっかやってます|うぇーい
A20: FALSE | B20: SWINGO | C20: https://twitter.com/SmartSpaceDogs | E20: 1NZy2TZyEiG1GGRs5ZDQLntC9FQup6uaQB
A21: FALSE | B21: 安心院まおら | E21: 13K4Gw6ZnStysneTeG1WN4FAJy5xARzL5M
A22: FALSE | B22: らくがきac | C22: https://twitter.com/rkgk_ac | E22: 183EeDkhhEUHzygiAKcnJxui1LvvaK631u
A23: FALSE | B23: Kassy | C23: https://twitter.com/kassy_nara | E23: https://xchain.io/address/1NDLa9HG3WsBuzn1x6RyPBHNipUHLyaE2h | F23: kasaneate.starfree.jp/mc/artist/#kassy_nara | G23: 私はRarepepe1作品、Memorychain7作品、Raredoge3作品(Rarereject2作品含む)を作成していますが、絵の描けない所謂なんちゃってクソコラアーティストです。
A24: FALSE | B24: ミツコア | C24: https://twitter.com/mizcored | E24: 1HPGQi58gwnRzUCgG7DMkZeNUN5ZmygxH
A25: FALSE | B25: たろふあ | E25: 1M9Spz7KDH2LwHsuCokBxnc9EvJ3dg11ZA
A26: FALSE | B26: VeryLongUnagi | E26: 1E8bCUjLUnwGDPxqbT1ZV58Nvw7e4yENCC
A27: FALSE | B27: 笑猫 | C27: https://twitter.com/1aughingcat | E27: https://xchain.io/address/18fXiDwiLAX2M3eUZqzRTcKvvAPiTTCiDK | G27: Twitter歴だけが長い暗号資産愛好者です。Memorychainを始めとしてOasismining、RAREPEPEのトークンを発行しています。トークンの画像は私のアイデアを元に友人の絵師に描いてもらっています。
A28: FALSE | B28: 裏技君 | C28: https://twitter.com/urawazakun | E28: 1CAGQNYiuxcPgAqM68Cj8uSYvHc1inc3sW
A29: FALSE | B29: 響 | C29: https://twitter.com/Whiskey_bonbon_ | E29: 1ANpJrYSRdeLnBYnfMp2gocR9RmXs5WNta
A30: FALSE | B30: 藤堂竜白 | C30: https://twitter.com/todokasumi | E30: 1A2ES1YxYQUgxNGt1KKLUABz4da2QPoK8J | H30: メモチェンカード図鑑(http://kasaneate.starfree.jp/mc/)・レアペペディレクトリ(http://kasaneate.starfree.jp/pepe/)管理人
A31: FALSE | B31: x0xb0x | C31: https://twitter.com/x0xb0x1 | E31: 1AKEuLtnq73BNQjHxU2BVoV4NQSEDDUATj | G31: ゆるいkojiフォロワーです。
A32: FALSE | B32: べた | C32: https://twitter.com/ethereumon | E32: 1GEqkXzCuz3uKmoSHj7gvMRP5PTTBBf2bn
A33: FALSE | B33: PJ | E33: 15S2QjogGf2S8TqmcuromRjmoAafhaoESw
A34: FALSE | B34: メルキャット | E34: 13FdXxyPmvMWBJ6izex2Vi7myYbLpMEPkf
A35: FALSE | B35: 栗饅頭 | E35: 19NhxkJtRBJa1RwHuv6vYGdTQeaegHQYYj
A36: FALSE | B36: 五所川原銭夫 | E36: 14Zw9Ro5aMAzQZu4GkjvV6uj3sEP59FzzL
A37: FALSE | B37: 睡眠 | E37: 14BERVmcqCfCsoEPT328JcDN5FPs6YZYtw
A38: FALSE | B38: Onigiri | C38: https://twitter.com/7cryptocurrency | E38: 1CSBaZDaS6i8yb9uvHiYe53Xca4NRnzLQc
A39: FALSE | B39: チノ | E39: 1QL9cXujxjw6Utd662mr668mDh7cCjbHe8
A40: FALSE | B40: M1XXK1NG W1CKED | E40: 16LcCPzKMzfpG7oMtkfAxKyraZU32vdtzB
...
